<html lang="en">

<head>
  <meta charset="UTF-8">
  <meta http-equiv="X-UA-Compatible" content="IE=edge">
  <meta name="viewport" content="width=device-width, initial-scale=1.0">
  <title>Document</title>
</head>

<body>
  <script>


    function ajax(str, boo, time) {
      return new Promise((reslove, reject) => {
        setTimeout(() => {
          boo ? reslove(str + "返回结果成功") : reject(str + "返回结果失败")
        }, time || 1000);
      });
    }

    // (async ()=>{
    //     //结论是  当不写catch错误处理  async 会直接向上抛错误 会导致await后面的方法不执行，需要在catch下
    //     await ajax("ajax",false).catch(res=>{
    //         console.log(res);
    //     })
    //     console.log(3);

    // })()
    async function middlePromise() {
      return await ajax("ajax", false).catch(err => {
        console.log("middlePromise", err);
      })
    }

    window.addEventListener("unhandledrejection", (e) => {
      console.log("promise 错误");
    })
      ; (async () => {
        //结论是  
        //1. 当不写catch错误处理 内部ajax也没有写reject 那么整个异常没办法捕获，情景是 await传递两次只返回reject的数据，会导致错误无法排查
        //2. 当不写catch错误处理 内部ajax有写reject,整个异常会抛向window，下面的语句不会执行(有可能是你需要的情况，错误就不执行)， 那么会进入unhandledrejection事件中，实际过程中需要最里层的请求捕获异常即可
        //3. 如果中间promise有异常捕获，那么最外层就不会抛向window，所以我们业务中应该封装在网络请求层捕获异常即可
        await middlePromise()
        console.log(3);

      })()

  </script>
</body>

</html>